[2020-06-12 15:16:21,024] {taskinstance.py:669} INFO - Dependencies all met for <TaskInstance: dataops.modeling 2020-06-11T00:00:00+00:00 [queued]>
[2020-06-12 15:16:21,052] {taskinstance.py:669} INFO - Dependencies all met for <TaskInstance: dataops.modeling 2020-06-11T00:00:00+00:00 [queued]>
[2020-06-12 15:16:21,052] {taskinstance.py:879} INFO - 
--------------------------------------------------------------------------------
[2020-06-12 15:16:21,052] {taskinstance.py:880} INFO - Starting attempt 10 of 13
[2020-06-12 15:16:21,052] {taskinstance.py:881} INFO - 
--------------------------------------------------------------------------------
[2020-06-12 15:16:21,070] {taskinstance.py:900} INFO - Executing <Task(BashOperator): modeling> on 2020-06-11T00:00:00+00:00
[2020-06-12 15:16:21,073] {standard_task_runner.py:53} INFO - Started process 24264 to run task
[2020-06-12 15:16:21,140] {logging_mixin.py:112} INFO - Running %s on host %s <TaskInstance: dataops.modeling 2020-06-11T00:00:00+00:00 [running]> vinicius-Latitude-3480
[2020-06-12 15:16:21,164] {bash_operator.py:82} INFO - Tmp dir root location: 
 /tmp
[2020-06-12 15:16:21,165] {bash_operator.py:103} INFO - Temporary script location: /tmp/airflowtmpfu6c4j8w/modelingfw5uwu55
[2020-06-12 15:16:21,165] {bash_operator.py:115} INFO - Running command: python /home/vinicius/Documents/Projetos/Claro/Piloto/git_Homologação/src/modeling/run.py
[2020-06-12 15:16:21,170] {bash_operator.py:122} INFO - Output:
[2020-06-12 15:17:46,210] {bash_operator.py:126} INFO - Treinando modelo KN_Test
[2020-06-12 15:17:46,210] {bash_operator.py:126} INFO - INFO: 'Test_model' does not exist. Creating a new experiment
[2020-06-12 15:17:46,210] {bash_operator.py:126} INFO - Treinando modelo KN_4
[2020-06-12 15:17:46,210] {bash_operator.py:126} INFO - Treinando modelo test_LR
[2020-06-12 15:17:46,211] {bash_operator.py:126} INFO - Traceback (most recent call last):
[2020-06-12 15:17:46,212] {bash_operator.py:126} INFO -   File "/home/vinicius/Documents/Projetos/Claro/Piloto/git_Homologação/src/modeling/run.py", line 103, in <module>
[2020-06-12 15:17:46,212] {bash_operator.py:126} INFO -     save_output(config_model,list_result,output_dict)
[2020-06-12 15:17:46,212] {bash_operator.py:126} INFO -   File "/home/vinicius/Documents/Projetos/Claro/Piloto/git_Homologação/src/modeling/run.py", line 47, in save_output
[2020-06-12 15:17:46,212] {bash_operator.py:126} INFO -     output_table.to_csv(f"{output_table_path}/{output_table_name}")
[2020-06-12 15:17:46,212] {bash_operator.py:126} INFO -   File "/home/vinicius/anaconda3/envs/claro_piloto_homolog/lib/python3.8/site-packages/pandas/core/generic.py", line 3228, in to_csv
[2020-06-12 15:17:46,212] {bash_operator.py:126} INFO -     formatter.save()
[2020-06-12 15:17:46,212] {bash_operator.py:126} INFO -   File "/home/vinicius/anaconda3/envs/claro_piloto_homolog/lib/python3.8/site-packages/pandas/io/formats/csvs.py", line 179, in save
[2020-06-12 15:17:46,212] {bash_operator.py:126} INFO -     f, handles = _get_handle(
[2020-06-12 15:17:46,212] {bash_operator.py:126} INFO -   File "/home/vinicius/anaconda3/envs/claro_piloto_homolog/lib/python3.8/site-packages/pandas/io/common.py", line 399, in _get_handle
[2020-06-12 15:17:46,212] {bash_operator.py:126} INFO -     f = open(path_or_buf, mode, encoding=encoding, newline="")
[2020-06-12 15:17:46,212] {bash_operator.py:126} INFO - FileNotFoundError: [Errno 2] No such file or directory: '/home/vinicius/Documents/Projetos/Claro/Piloto/git_Homologação/src/modeling/output/model_output_85866.csv'
[2020-06-12 15:17:46,527] {bash_operator.py:128} INFO - Command exited with return code 1
[2020-06-12 15:17:46,541] {taskinstance.py:1145} ERROR - Bash command failed
Traceback (most recent call last):
  File "/home/vinicius/anaconda3/envs/claro_piloto_homolog/lib/python3.8/site-packages/airflow/models/taskinstance.py", line 983, in _run_raw_task
    result = task_copy.execute(context=context)
  File "/home/vinicius/anaconda3/envs/claro_piloto_homolog/lib/python3.8/site-packages/airflow/operators/bash_operator.py", line 134, in execute
    raise AirflowException("Bash command failed")
airflow.exceptions.AirflowException: Bash command failed
[2020-06-12 15:17:46,543] {taskinstance.py:1168} INFO - Marking task as UP_FOR_RETRY
[2020-06-12 15:17:51,618] {logging_mixin.py:112} INFO - [2020-06-12 15:17:51,617] {local_task_job.py:103} INFO - Task exited with return code 1
