[2020-06-11 03:00:19,310] {taskinstance.py:669} INFO - Dependencies all met for <TaskInstance: dataops.modeling 2020-06-11T00:00:00+00:00 [queued]>
[2020-06-11 03:00:19,410] {taskinstance.py:669} INFO - Dependencies all met for <TaskInstance: dataops.modeling 2020-06-11T00:00:00+00:00 [queued]>
[2020-06-11 03:00:19,410] {taskinstance.py:879} INFO - 
--------------------------------------------------------------------------------
[2020-06-11 03:00:19,411] {taskinstance.py:880} INFO - Starting attempt 3 of 6
[2020-06-11 03:00:19,411] {taskinstance.py:881} INFO - 
--------------------------------------------------------------------------------
[2020-06-11 03:00:19,452] {taskinstance.py:900} INFO - Executing <Task(BashOperator): modeling> on 2020-06-11T00:00:00+00:00
[2020-06-11 03:00:19,455] {standard_task_runner.py:53} INFO - Started process 19829 to run task
[2020-06-11 03:00:19,561] {logging_mixin.py:112} INFO - Running %s on host %s <TaskInstance: dataops.modeling 2020-06-11T00:00:00+00:00 [running]> vinicius-Latitude-3480
[2020-06-11 03:00:19,595] {bash_operator.py:82} INFO - Tmp dir root location: 
 /tmp
[2020-06-11 03:00:19,597] {bash_operator.py:105} INFO - Temporary script location: /tmp/airflowtmpuilds2a2/modelingxg9j4ayl
[2020-06-11 03:00:19,597] {bash_operator.py:115} INFO - Running command: python /home/vinicius/Documents/Projetos/Claro/Piloto/git_Homologação/src/modeling/run.py
[2020-06-11 03:00:19,606] {bash_operator.py:122} INFO - Output:
[2020-06-11 03:01:26,588] {bash_operator.py:126} INFO - Treinando modelo KN_3
[2020-06-11 03:01:26,588] {bash_operator.py:126} INFO - INFO: 'Test_model' does not exist. Creating a new experiment
[2020-06-11 03:01:26,588] {bash_operator.py:126} INFO - Traceback (most recent call last):
[2020-06-11 03:01:26,589] {bash_operator.py:126} INFO -   File "/home/vinicius/Documents/Projetos/Claro/Piloto/git_Homologação/src/modeling/run.py", line 104, in <module>
[2020-06-11 03:01:26,589] {bash_operator.py:126} INFO -     save_mlflow(model,result,config_model)
[2020-06-11 03:01:26,589] {bash_operator.py:126} INFO -   File "/home/vinicius/Documents/Projetos/Claro/Piloto/git_Homologação/src/modeling/run.py", line 20, in save_mlflow
[2020-06-11 03:01:26,589] {bash_operator.py:126} INFO -     if 'run_name' in config_model['models'][model_name].keys():
[2020-06-11 03:01:26,589] {bash_operator.py:126} INFO - KeyError: 'KNeighborsRegressor'
[2020-06-11 03:01:26,916] {bash_operator.py:130} INFO - Command exited with return code 1
[2020-06-11 03:01:26,928] {taskinstance.py:1145} ERROR - Bash command failed
Traceback (most recent call last):
  File "/home/vinicius/anaconda3/lib/python3.7/site-packages/airflow/models/taskinstance.py", line 983, in _run_raw_task
    result = task_copy.execute(context=context)
  File "/home/vinicius/anaconda3/lib/python3.7/site-packages/airflow/operators/bash_operator.py", line 134, in execute
    raise AirflowException("Bash command failed")
airflow.exceptions.AirflowException: Bash command failed
[2020-06-11 03:01:26,930] {taskinstance.py:1168} INFO - Marking task as UP_FOR_RETRY
[2020-06-11 03:01:29,724] {logging_mixin.py:112} INFO - [2020-06-11 03:01:29,724] {local_task_job.py:103} INFO - Task exited with return code 1
