[2020-06-11 02:37:32,937] {taskinstance.py:669} INFO - Dependencies all met for <TaskInstance: dataops.unit_test 2020-06-11T00:00:00+00:00 [queued]>
[2020-06-11 02:37:32,973] {taskinstance.py:669} INFO - Dependencies all met for <TaskInstance: dataops.unit_test 2020-06-11T00:00:00+00:00 [queued]>
[2020-06-11 02:37:32,973] {taskinstance.py:879} INFO - 
--------------------------------------------------------------------------------
[2020-06-11 02:37:32,973] {taskinstance.py:880} INFO - Starting attempt 4 of 4
[2020-06-11 02:37:32,973] {taskinstance.py:881} INFO - 
--------------------------------------------------------------------------------
[2020-06-11 02:37:32,999] {taskinstance.py:900} INFO - Executing <Task(BashOperator): unit_test> on 2020-06-11T00:00:00+00:00
[2020-06-11 02:37:33,002] {standard_task_runner.py:53} INFO - Started process 30785 to run task
[2020-06-11 02:37:33,092] {logging_mixin.py:112} INFO - Running %s on host %s <TaskInstance: dataops.unit_test 2020-06-11T00:00:00+00:00 [running]> vinicius-Latitude-3480
[2020-06-11 02:37:33,117] {bash_operator.py:82} INFO - Tmp dir root location: 
 /tmp
[2020-06-11 02:37:33,118] {bash_operator.py:105} INFO - Temporary script location: /tmp/airflowtmpcdw_r82a/unit_testibtymzf5
[2020-06-11 02:37:33,118] {bash_operator.py:115} INFO - Running command: python /home/vinicius/Documents/Projetos/Claro/Piloto/git_Homologação/src/unit_test/unit_test.py
[2020-06-11 02:37:33,124] {bash_operator.py:122} INFO - Output:
[2020-06-11 02:37:33,694] {bash_operator.py:126} INFO - Iniciando tests...
[2020-06-11 02:37:33,694] {bash_operator.py:126} INFO - Traceback (most recent call last):
[2020-06-11 02:37:33,694] {bash_operator.py:126} INFO -   File "/home/vinicius/Documents/Projetos/Claro/Piloto/git_Homologação/src/unit_test/unit_test.py", line 34, in <module>
[2020-06-11 02:37:33,694] {bash_operator.py:126} INFO -     config_file = open(data_config_path)
[2020-06-11 02:37:33,694] {bash_operator.py:126} INFO - FileNotFoundError: [Errno 2] No such file or directory: '../../config/data_config.yaml'
[2020-06-11 02:37:33,786] {bash_operator.py:130} INFO - Command exited with return code 1
[2020-06-11 02:37:33,803] {taskinstance.py:1145} ERROR - Bash command failed
Traceback (most recent call last):
  File "/home/vinicius/anaconda3/lib/python3.7/site-packages/airflow/models/taskinstance.py", line 983, in _run_raw_task
    result = task_copy.execute(context=context)
  File "/home/vinicius/anaconda3/lib/python3.7/site-packages/airflow/operators/bash_operator.py", line 134, in execute
    raise AirflowException("Bash command failed")
airflow.exceptions.AirflowException: Bash command failed
[2020-06-11 02:37:33,805] {taskinstance.py:1187} INFO - All retries failed; marking task as FAILED.dag_id=dataops, task_id=unit_test, execution_date=20200611T000000, start_date=20200611T053732, end_date=20200611T053733
[2020-06-11 02:37:42,870] {logging_mixin.py:112} INFO - [2020-06-11 02:37:42,869] {local_task_job.py:103} INFO - Task exited with return code 1
